Workbook
Name Datenschnitt_Channel: #N/A
Name Datenschnitt_Country: #N/A
Name Datenschnitt_Product_Category: #N/A

Sheet Dashboard
A1: Sales & Market Performance Dashboard
P2: =Pivot_Analysis!C63/1000000 -> 144.08589
A3: Jan–Aug 2026 YTD | Comparison vs Jan–Aug 2025 | Synthetic portfolio dataset | P3: =Pivot_Analysis!D63 -> 0.095085691
P4: =Pivot_Analysis!C63/Pivot_Analysis!C67 -> 1.0202489
P5: =Pivot_Analysis!C65/Pivot_Analysis!C63 -> 0.59739122
A6: Revenue | D6: Revenue YoY | F6: Target Attainment | H6: Gross Margin | K6: Market Share | P6: =Pivot_Analysis!C63/Pivot_Analysis!C66 -> 0.13727863
A7: =P2 -> 144.08589 | D7: =P3 -> 0.095085691 | F7: =P4 -> 1.0202489 | H7: =P5 -> 0.59739122 | K7: =P6 -> 0.13727863
A9: Jan–Aug 2026 YTD | D9: vs Jan–Aug 2025 | F9: vs YTD target | H9: Jan–Aug 2026 YTD | K9: +0,16 pp vs 2025 YTD
A55: Key findings | J55: Data note
A56: 1 | B56: Revenue grew 9.5% YTD, ahead of market growth of 8.3%, increasing market share by 0.16 pp to 13.73%. | J56: Synthetic dataset created for portfolio purposes; no proprietary company data is used.
A58: 2 | B58: Progressive and Single Vision are the largest revenue categories, contributing approximately €53m and €51m respectively.
A60: 3 | B60: Germany is the largest revenue market and also has the highest market share, while Austria combines relatively low absolute revenue with a comparatively strong market share.

Sheet Project_Brief
A1: Sales & Market Performance Dashboard
A3: Portfolio case | Synthetic European optical sales data | Data cut: August 2026
A5: Objective | B5: Build an Excel dashboard that explains sales performance, target attainment, profitability and market-share development across countries, channels and product categories.
A6: Data period | B6: January 2023 – August 2026
A7: Geography | B7: Germany, France, Italy, Spain, Netherlands, Poland and Austria
A8: Channels | B8: Independent Opticians, Optical Chains, E-commerce
A9: Product categories | B9: Single Vision, Progressive, Myopia Management, Occupational / Digital
A11: Business questions to answer
A12: 1. Is revenue growing, and which countries/products are driving the change?
A13: 2. Which markets are above or below revenue target?
A14: 3. How are units and average selling price developing?
A15: 4. Which product categories have the highest gross margin?
A16: 5. Where is company market share gaining or losing?
A17: 6. How do Independent Opticians, Optical Chains and E-commerce differ?
A18: 7. Which countries/categories deserve management attention?
A20: Recommended dashboard KPIs
A21: KPI | B21: Suggested formula / logic | C21: Why it matters | D21: Type | F21: KPI | G21: Suggested formula / logic | H21: Why it matters | I21: Type
A22: Revenue | B22: SUM(Revenue_EUR) | C22: Top-line performance | D22: Core | F22: Unit growth | G22: YoY % change in Units_Sold | H22: Volume performance | I22: Additional
A23: Revenue target attainment | B23: Revenue / Revenue_Target | C23: Plan vs. actual | D23: Core | F23: Return rate | G23: Returns_Units / Units_Sold | H23: Quality / channel signal | I23: Additional
A24: Gross margin % | B24: Gross_Profit / Revenue | C24: Profitability | D24: Core | F24: Marketing efficiency | G24: Revenue / Marketing_Spend | H24: Commercial efficiency | I24: Additional
A25: Market share % | B25: Revenue / Market_Revenue | C25: Competitive performance | D25: Core | F25: New accounts | G25: SUM(New_Accounts) | H25: Customer acquisition | I25: Additional
A26: YoY revenue growth | B26: (Current year / prior year) - 1 | C26: Growth trend | D26: Core | F26: YoY revenue growth | G26: (Current year / prior year) - 1 | H26: Growth trend | I26: Additional
F27: Average selling price | G27: Revenue / Units_Sold | H27: Price / mix development | I27: Additional
A28: IMPORTANT: All numbers in this workbook are synthetic and were generated specifically for portfolio practice. They do not represent Rodenstock, EssilorLuxottica, ZEISS, HOYA or any other real company.

Sheet Pivot_Analysis
A1: Pivot Analysis
A5: Year | B5: (Alle) | D5: Year | E5: (Alle)
A7: Country | B7: Revenue | D7: Country | E7: Revenue | F7: Revenue Target | G7: Target Attainment %
A8: Germany | B8: 2.4534997e+08 | D8: Germany | E8: 2.4534997e+08 | F8: 2.3582492e+08 | G8: =E8/F8 -> 1.0403903
A9: France | B9: 1.386821e+08 | D9: France | E9: 1.386821e+08 | F9: 1.455723e+08 | G9: =E9/F9 -> 0.95266816
A10: Italy | B10: 93843830 | D10: Italy | E10: 93843830 | F10: 93673718 | G10: =E10/F10 -> 1.001816
A11: Spain | B11: 76662099 | D11: Spain | E11: 76662099 | F11: 72221539 | G11: =E11/F11 -> 1.0614853
A12: Netherlands | B12: 57977366 | D12: Netherlands | E12: 57977366 | F12: 56884632 | G12: =E12/F12 -> 1.0192097
A13: Austria | B13: 47065985 | D13: Austria | E13: 47065985 | F13: 46525669 | G13: =E13/F13 -> 1.0116133
A14: Poland | B14: 47053772 | D14: Poland | E14: 47053772 | F14: 44660605 | G14: =E14/F14 -> 1.0535857
A15: Total | B15: 7.0663511e+08 | D15: Total | E15: 7.0663511e+08 | F15: 6.9536339e+08 | G15: =E15/F15 -> 1.0162098
A18: Year | B18: (Alle)
A20: Product_Category | B20: Revenue | C20: Gross Profit | D20: Units Sold | E20: Gross Margin
A21: Single Vision | B21: 2.6377776e+08 | C21: 1.4270397e+08 | D21: 3527742 | E21: =C21/B21 -> 0.54100075
A22: Progressive | B22: 2.6142731e+08 | C22: 1.6503034e+08 | D22: 1397530 | E22: =C22/B22 -> 0.63126661
A23: Occupational / Digital | B23: 1.0936491e+08 | C23: 65779337 | D23: 914348 | E23: =C23/B23 -> 0.60146659
A24: Myopia Management | B24: 72065133 | C24: 47664785 | D24: 493090 | E24: =C24/B24 -> 0.66141258
A25: Total | B25: 7.0663511e+08 | C25: 4.2117842e+08 | D25: 6332710 | E25: =C25/B25 -> 0.59603382
A28: Year | B28: (Alle)
A30: Channel | B30: Revenue | C30: Units Sold | D30: Returns Units | E30: Gross Profit | F30: Marketing Spend | G30: Return Rate % | H30: Revenue per Marketing | I30: Gross Margin
A31: Independent Opticians | B31: 3.6421048e+08 | C31: 3264773 | D31: 48443 | E31: 2.2526336e+08 | F31: 9534477.6 | G31: =D31/C31 -> 0.014838091 | H31: =B31/F31 -> 38.199312 | I31: =E31/B31 -> 0.61849773
A32: Optical Chains | B32: 3.1033907e+08 | C32: 2782642 | D32: 41883 | E32: 1.7911321e+08 | F32: 8132648.7 | G32: =D32/C32 -> 0.015051523 | H32: =B32/F32 -> 38.159655 | I32: =E32/B32 -> 0.57715326
A33: E-commerce | B33: 32085560 | C33: 285295 | D33: 6634 | E33: 16801861 | F33: 844310.88 | G33: =D33/C33 -> 0.023253124 | H33: =B33/F33 -> 38.002068 | I33: =E33/B33 -> 0.52365803
A34: Total | B34: 7.0663511e+08 | C34: 6332710 | D34: 96960 | E34: 4.2117842e+08 | F34: 18511437 | G34: =D34/C34 -> 0.015310981 | H34: =B34/F34 -> 38.172893 | I34: =E34/B34 -> 0.59603382
A37: Year | B37: (Alle)
A39: Country | B39: Revenue | C39: Market Revenue | D39: Market Share
A40: Germany | B40: 2.4534997e+08 | C40: 1.3934312e+09 | D40: =B40/C40 -> 0.17607612
A41: France | B41: 1.386821e+08 | C41: 1.0850224e+09 | D41: =B41/C41 -> 0.12781496
A42: Italy | B42: 93843830 | C42: 8.2559285e+08 | D42: =B42/C42 -> 0.11366841
A43: Spain | B43: 76662099 | C43: 7.0985508e+08 | D43: =B43/C43 -> 0.10799683
A44: Netherlands | B44: 57977366 | C44: 3.9751795e+08 | D44: =B44/C44 -> 0.14584842
A45: Austria | B45: 47065985 | C45: 2.9977579e+08 | D45: =B45/C45 -> 0.15700396
A46: Poland | B46: 47053772 | C46: 5.0421388e+08 | D46: =B46/C46 -> 0.093321057
A47: Total | B47: 7.0663511e+08 | C47: 5.2154092e+09 | D47: =B47/C47 -> 0.13548987
A51: Year | B51: Revenue | C51: Revenue YoY % | D51: Units Sold | E51: Units YoY % | F51: Gross Profit | G51: Gross Profit YoY % | H51: Market Revenue | I51: Market Revenue YoY %
A52: 2023 | B52: 1.7375033e+08 | D52: 1650835 | F52: 1.0333258e+08 | H52: 1.286704e+09
A53: 2024 | B53: 1.8579571e+08 | C53: 0.069325803 | D53: 1696230 | E53: 0.027498205 | F53: 1.1058374e+08 | G53: 0.070173027 | H53: 1.3856103e+09 | I53: 0.076867977
A54: 2025 | B54: 2.0300319e+08 | C54: 0.092615051 | D54: 1773215 | E54: 0.045385944 | F54: 1.2118647e+08 | G54: 0.095879635 | H54: 1.4935077e+09 | I54: 0.077869947
A55: Total | B55: 5.6254922e+08 | D55: 5120280 | F55: 3.3510278e+08 | H55: 4.165822e+09
A59: Month_Name | B59: (Mehrere Elemente)
...

Sheet Clean_Data
A1: Month | B1: Year | C1: Month_Name | D1: Country | E1: Region | F1: Channel | G1: Product_Category | H1: Revenue_EUR | I1: Revenue_Target_EUR | J1: Units_Sold | K1: Units_Target | L1: Gross_Profit_EUR | M1: Marketing_Spend_EUR | N1: Market_Revenue_EUR | O1: Market_Units | P1: New_Accounts | Q1: Returns_Units | R1: ASP_EUR | S1: Gross_Margin_% | T1: Revenue_Target_Attainment_% | U1: Market_Share_% | V1: Return_Rate_% | W1: Revenue_per_Marketing_EUR
A2: 44927 | B2: 2023 | C2: Jan | D2: Germany | E2: DACH | F2: Independent Opticians | G2: Single Vision | H2: 954664.99 | I2: 919123.74 | J2: 13259 | K2: 12809 | L2: 532521.38 | M2: 16232.7 | N2: 5924182.3 | O2: 89223 | P2: 52 | Q2: 122 | R2: =Clean_Data[[#This Row],[Revenue_EUR]]/Clean_Data[[#This Row],[Units_Sold]] -> 72.001281 | S2: =Clean_Data[[#This Row],[Gross_Profit_EUR]]/Clean_Data[[#This Row],[Revenue_EUR]] -> 0.55780969 | T2: =Clean_Data[[#This Row],[Revenue_EUR]]/Clean_Data[[#This Row],[Revenue_Target_EUR]] -> 1.0386686 | U2: =Clean_Data[[#This Row],[Revenue_EUR]]/Clean_Data[[#This Row],[Market_Revenue_EUR]] -> 0.16114713 | V2: =Clean_Data[[#This Row],[Returns_Units]]/Clean_Data[[#This Row],[Units_Sold]] -> 0.0092012972 | W2: =Clean_Data[[#This Row],[Revenue_EUR]]/Clean_Data[[#This Row],[Marketing_Spend_EUR]] -> 58.811226
A3: 44927 | B3: 2023 | C3: Jan | D3: Germany | E3: DACH | F3: Independent Opticians | G3: Progressive | H3: 877806.91 | I3: 859854.25 | J3: 5016 | K3: 4935 | L3: 575231.49 | M3: 19867.12 | N3: 4430206.7 | O3: 26962 | P3: 42 | Q3: 56 | R3: =Clean_Data[[#This Row],[Revenue_EUR]]/Clean_Data[[#This Row],[Units_Sold]] -> 175.00138 | S3: =Clean_Data[[#This Row],[Gross_Profit_EUR]]/Clean_Data[[#This Row],[Revenue_EUR]] -> 0.65530527 | T3: =Clean_Data[[#This Row],[Revenue_EUR]]/Clean_Data[[#This Row],[Revenue_Target_EUR]] -> 1.0208787 | U3: =Clean_Data[[#This Row],[Revenue_EUR]]/Clean_Data[[#This Row],[Market_Revenue_EUR]] -> 0.1981413 | V3: =Clean_Data[[#This Row],[Returns_Units]]/Clean_Data[[#This Row],[Units_Sold]] -> 0.011164274 | W3: =Clean_Data[[#This Row],[Revenue_EUR]]/Clean_Data[[#This Row],[Marketing_Spend_EUR]] -> 44.183903
A4: 44927 | B4: 2023 | C4: Jan | D4: Germany | E4: DACH | F4: Independent Opticians | G4: Myopia Management | H4: 206834.21 | I4: 194026.17 | J4: 1477 | K4: 1403 | L4: 143273.53 | M4: 11826.68 | N4: 1429491.4 | O4: 11482 | P4: 12 | Q4: 19 | R4: =Clean_Data[[#This Row],[Revenue_EUR]]/Clean_Data[[#This Row],[Units_Sold]] -> 140.0367 | S4: =Clean_Data[[#This Row],[Gross_Profit_EUR]]/Clean_Data[[#This Row],[Revenue_EUR]] -> 0.69269745 | T4: =Clean_Data[[#This Row],[Revenue_EUR]]/Clean_Data[[#This Row],[Revenue_Target_EUR]] -> 1.0660119 | U4: =Clean_Data[[#This Row],[Revenue_EUR]]/Clean_Data[[#This Row],[Market_Revenue_EUR]] -> 0.14469076 | V4: =Clean_Data[[#This Row],[Returns_Units]]/Clean_Data[[#This Row],[Units_Sold]] -> 0.012863913 | W4: =Clean_Data[[#This Row],[Revenue_EUR]]/Clean_Data[[#This Row],[Marketing_Spend_EUR]] -> 17.48878
A5: 44927 | B5: 2023 | C5: Jan | D5: Germany | E5: DACH | F5: Independent Opticians | G5: Occupational / Digital | H5: 389302.27 | I5: 374411.34 | J5: 3385 | K5: 3215 | L5: 243680.54 | M5: 12396.46 | N5: 2024932.3 | O5: 18828 | P5: 22 | Q5: 45 | R5: =Clean_Data[[#This Row],[Revenue_EUR]]/Clean_Data[[#This Row],[Units_Sold]] -> 115.00806 | S5: =Clean_Data[[#This Row],[Gross_Profit_EUR]]/Clean_Data[[#This Row],[Revenue_EUR]] -> 0.62594174 | T5: =Clean_Data[[#This Row],[Revenue_EUR]]/Clean_Data[[#This Row],[Revenue_Target_EUR]] -> 1.0397716 | U5: =Clean_Data[[#This Row],[Revenue_EUR]]/Clean_Data[[#This Row],[Market_Revenue_EUR]] -> 0.19225447 | V5: =Clean_Data[[#This Row],[Returns_Units]]/Clean_Data[[#This Row],[Units_Sold]] -> 0.013293944 | W5: =Clean_Data[[#This Row],[Revenue_EUR]]/Clean_Data[[#This Row],[Marketing_Spend_EUR]] -> 31.40431
A6: 44927 | B6: 2023 | C6: Jan | D6: Germany | E6: DACH | F6: Optical Chains | G6: Single Vision | H6: 842749.23 | I6: 858430.26 | J6: 11705 | K6: 11888 | L6: 446222.12 | M6: 15404.16 | N6: 5105569.3 | O6: 79856 | P6: 35 | Q6: 141 | R6: =Clean_Data[[#This Row],[Revenue_EUR]]/Clean_Data[[#This Row],[Units_Sold]] -> 71.99908 | S6: =Clean_Data[[#This Row],[Gross_Profit_EUR]]/Clean_Data[[#This Row],[Revenue_EUR]] -> 0.52948387 | T6: =Clean_Data[[#This Row],[Revenue_EUR]]/Clean_Data[[#This Row],[Revenue_Target_EUR]] -> 0.9817329 | U6: =Clean_Data[[#This Row],[Revenue_EUR]]/Clean_Data[[#This Row],[Market_Revenue_EUR]] -> 0.16506469 | V6: =Clean_Data[[#This Row],[Returns_Units]]/Clean_Data[[#This Row],[Units_Sold]] -> 0.012046134 | W6: =Clean_Data[[#This Row],[Revenue_EUR]]/Clean_Data[[#This Row],[Marketing_Spend_EUR]] -> 54.709197
A7: 44927 | B7: 2023 | C7: Jan | D7: Germany | E7: DACH | F7: Optical Chains | G7: Progressive | H7: 711249.36 | I7: 661325.09 | J7: 4064 | K7: 3837 | L7: 431749.41 | M7: 18263.76 | N7: 3824968.6 | O7: 22448 | P7: 29 | Q7: 48 | R7: =Clean_Data[[#This Row],[Revenue_EUR]]/Clean_Data[[#This Row],[Units_Sold]] -> 175.01215 | S7: =Clean_Data[[#This Row],[Gross_Profit_EUR]]/Clean_Data[[#This Row],[Revenue_EUR]] -> 0.60702959 | T7: =Clean_Data[[#This Row],[Revenue_EUR]]/Clean_Data[[#This Row],[Revenue_Target_EUR]] -> 1.0754913 | U7: =Clean_Data[[#This Row],[Revenue_EUR]]/Clean_Data[[#This Row],[Market_Revenue_EUR]] -> 0.18594907 | V7: =Clean_Data[[#This Row],[Returns_Units]]/Clean_Data[[#This Row],[Units_Sold]] -> 0.011811024 | W7: =Clean_Data[[#This Row],[Revenue_EUR]]/Clean_Data[[#This Row],[Marketing_Spend_EUR]] -> 38.943206
A8: 44927 | B8: 2023 | C8: Jan | D8: Germany | E8: DACH | F8: Optical Chains | G8: Myopia Management | H8: 177838.36 | I8: 169497.6 | J8: 1270 | K8: 1228 | L8: 112728.87 | M8: 10229.33 | N8: 1198426.6 | O8: 9148 | P8: 10 | Q8: 22 | R8: =Clean_Data[[#This Row],[Revenue_EUR]]/Clean_Data[[#This Row],[Units_Sold]] -> 140.0302 | S8: =Clean_Data[[#This Row],[Gross_Profit_EUR]]/Clean_Data[[#This Row],[Revenue_EUR]] -> 0.63388388 | T8: =Clean_Data[[#This Row],[Revenue_EUR]]/Clean_Data[[#This Row],[Revenue_Target_EUR]] -> 1.0492087 | U8: =Clean_Data[[#This Row],[Revenue_EUR]]/Clean_Data[[#This Row],[Market_Revenue_EUR]] -> 0.1483932 | V8: =Clean_Data[[#This Row],[Returns_Units]]/Clean_Data[[#This Row],[Units_Sold]] -> 0.017322835 | W8: =Clean_Data[[#This Row],[Revenue_EUR]]/Clean_Data[[#This Row],[Marketing_Spend_EUR]] -> 17.385143
A9: 44927 | B9: 2023 | C9: Jan | D9: Germany | E9: DACH | F9: Optical Chains | G9: Occupational / Digital | H9: 329922.34 | I9: 321334.44 | J9: 2869 | K9: 2832 | L9: 193604.68 | M9: 9361.31 | N9: 1802838.9 | O9: 16091 | P9: 14 | Q9: 31 | R9: =Clean_Data[[#This Row],[Revenue_EUR]]/Clean_Data[[#This Row],[Units_Sold]] -> 114.99559 | S9: =Clean_Data[[#This Row],[Gross_Profit_EUR]]/Clean_Data[[#This Row],[Revenue_EUR]] -> 0.58681895 | T9: =Clean_Data[[#This Row],[Revenue_EUR]]/Clean_Data[[#This Row],[Revenue_Target_EUR]] -> 1.0267257 | U9: =Clean_Data[[#This Row],[Revenue_EUR]]/Clean_Data[[#This Row],[Market_Revenue_EUR]] -> 0.18300157 | V9: =Clean_Data[[#This Row],[Returns_Units]]/Clean_Data[[#This Row],[Units_Sold]] -> 0.010805159 | W9: =Clean_Data[[#This Row],[Revenue_EUR]]/Clean_Data[[#This Row],[Marketing_Spend_EUR]] -> 35.243181
A10: 44927 | B10: 2023 | C10: Jan | D10: Germany | E10: DACH | F10: E-commerce | G10: Single Vision | H10: 65234.13 | I10: 66011.69 | J10: 906 | K10: 910 | L10: 31143.81 | M10: 1149.7 | N10: 569362.07 | O10: 8447 | P10: 3 | Q10: 16 | R10: =Clean_Data[[#This Row],[Revenue_EUR]]/Clean_Data[[#This Row],[Units_Sold]] -> 72.002351 | S10: =Clean_Data[[#This Row],[Gross_Profit_EUR]]/Clean_Data[[#This Row],[Revenue_EUR]] -> 0.47741589 | T10: =Clean_Data[[#This Row],[Revenue_EUR]]/Clean_Data[[#This Row],[Revenue_Target_EUR]] -> 0.98822087 | U10: =Clean_Data[[#This Row],[Revenue_EUR]]/Clean_Data[[#This Row],[Market_Revenue_EUR]] -> 0.11457407 | V10: =Clean_Data[[#This Row],[Returns_Units]]/Clean_Data[[#This Row],[Units_Sold]] -> 0.017660044 | W10: =Clean_Data[[#This Row],[Revenue_EUR]]/Clean_Data[[#This Row],[Marketing_Spend_EUR]] -> 56.740132
A11: 44927 | B11: 2023 | C11: Jan | D11: Germany | E11: DACH | F11: E-commerce | G11: Progressive | H11: 60515.71 | I11: 56283.8 | J11: 346 | K11: 325 | L11: 33950.32 | M11: 1482.45 | N11: 426037.07 | O11: 2752 | P11: 3 | Q11: 5 | R11: =Clean_Data[[#This Row],[Revenue_EUR]]/Clean_Data[[#This Row],[Units_Sold]] -> 174.9009 | S11: =Clean_Data[[#This Row],[Gross_Profit_EUR]]/Clean_Data[[#This Row],[Revenue_EUR]] -> 0.56101664 | T11: =Clean_Data[[#This Row],[Revenue_EUR]]/Clean_Data[[#This Row],[Revenue_Target_EUR]] -> 1.0751888 | U11: =Clean_Data[[#This Row],[Revenue_EUR]]/Clean_Data[[#This Row],[Market_Revenue_EUR]] -> 0.1420433 | V11: =Clean_Data[[#This Row],[Returns_Units]]/Clean_Data[[#This Row],[Units_Sold]] -> 0.014450867 | W11: =Clean_Data[[#This Row],[Revenue_EUR]]/Clean_Data[[#This Row],[Marketing_Spend_EUR]] -> 40.821417
A12: 44927 | B12: 2023 | C12: Jan | D12: Germany | E12: DACH | F12: E-commerce | G12: Myopia Management | H12: 13651.02 | I12: 12677.51 | J12: 98 | K12: 90 | L12: 7997.98 | M12: 739.12 | N12: 127490.39 | O12: 932 | P12: 1 | Q12: 2 | R12: =Clean_Data[[#This Row],[Revenue_EUR]]/Clean_Data[[#This Row],[Units_Sold]] -> 139.29612 | S12: =Clean_Data[[#This Row],[Gross_Profit_EUR]]/Clean_Data[[#This Row],[Revenue_EUR]] -> 0.58588882 | T12: =Clean_Data[[#This Row],[Revenue_EUR]]/Clean_Data[[#This Row],[Revenue_Target_EUR]] -> 1.0767903 | U12: =Clean_Data[[#This Row],[Revenue_EUR]]/Clean_Data[[#This Row],[Market_Revenue_EUR]] -> 0.10707489 | V12: =Clean_Data[[#This Row],[Returns_Units]]/Clean_Data[[#This Row],[Units_Sold]] -> 0.020408163 | W12: =Clean_Data[[#This Row],[Revenue_EUR]]/Clean_Data[[#This Row],[Marketing_Spend_EUR]] -> 18.469288
A13: 44927 | B13: 2023 | C13: Jan | D13: Germany | E13: DACH | F13: E-commerce | G13: Occupational / Digital | H13: 24196.11 | I13: 23567.12 | J13: 210 | K13: 206 | L13: 12860.14 | M13: 752.26 | N13: 203097.43 | O13: 1912 | P13: 1 | Q13: 3 | R13: =Clean_Data[[#This Row],[Revenue_EUR]]/Clean_Data[[#This Row],[Units_Sold]] -> 115.21957 | S13: =Clean_Data[[#This Row],[Gross_Profit_EUR]]/Clean_Data[[#This Row],[Revenue_EUR]] -> 0.53149618 | T13: =Clean_Data[[#This Row],[Revenue_EUR]]/Clean_Data[[#This Row],[Revenue_Target_EUR]] -> 1.0266893 | U13: =Clean_Data[[#This Row],[Revenue_EUR]]/Clean_Data[[#This Row],[Market_Revenue_EUR]] -> 0.11913548 | V13: =Clean_Data[[#This Row],[Returns_Units]]/Clean_Data[[#This Row],[Units_Sold]] -> 0.014285714 | W13: =Clean_Data[[#This Row],[Revenue_EUR]]/Clean_Data[[#This Row],[Marketing_Spend_EUR]] -> 32.164557
... A3697: 46235 | B3697: 2026 | C3697: Aug | D3697: Austria | E3697: DACH | F3697: E-commerce | G3697: Occupational / Digital | H3697: 9531.43 | I3697: 9731.11 | J3697: 76 | K3697: 78 | L3697: 5092.84 | M3697: 299.15 | N3697: 83197.52 | O3697: 724 | P3697: 1 | Q3697: 2 | R3697: =Clean_Data[[#This Row],[Revenue_EUR]]/Clean_Data[[#This Row],[Units_Sold]] -> 125.41355 | S3697: =Clean_Data[[#This Row],[Gross_Profit_EUR]]/Clean_Data[[#This Row],[Revenue_EUR]] -> 0.53432066 | T3697: =Clean_Data[[#This Row],[Revenue_EUR]]/Clean_Data[[#This Row],[Revenue_Target_EUR]] -> 0.97948024 | U3697: =Clean_Data[[#This Row],[Revenue_EUR]]/Clean_Data[[#This Row],[Market_Revenue_EUR]] -> 0.11456387 | V3697: =Clean_Data[[#This Row],[Returns_Units]]/Clean_Data[[#This Row],[Units_Sold]] -> 0.026315789 | W3697: =Clean_Data[[#This Row],[Revenue_EUR]]/Clean_Data[[#This Row],[Marketing_Spend_EUR]] -> 31.861708

Sheet Raw_Data
A1: Month | B1: Year | C1: Month_Name | D1: Country | E1: Region | F1: Channel | G1: Product_Category | H1: Revenue_EUR | I1: Revenue_Target_EUR | J1: Units_Sold | K1: Units_Target | L1: Gross_Profit_EUR | M1: Marketing_Spend_EUR | N1: Market_Revenue_EUR | O1: Market_Units | P1: New_Accounts | Q1: Returns_Units
A2: 44927 | B2: 2023 | C2: Jan | D2: Germany | E2: DACH | F2: Independent Opticians | G2: Single Vision | H2: 954664.99 | I2: 919123.74 | J2: 13259 | K2: 12809 | L2: 532521.38 | M2: 16232.7 | N2: 5924182.3 | O2: 89223 | P2: 52 | Q2: 122
A3: 44927 | B3: 2023 | C3: Jan | D3: Germany | E3: DACH | F3: Independent Opticians | G3: Progressive | H3: 877806.91 | I3: 859854.25 | J3: 5016 | K3: 4935 | L3: 575231.49 | M3: 19867.12 | N3: 4430206.7 | O3: 26962 | P3: 42 | Q3: 56
A4: 44927 | B4: 2023 | C4: Jan | D4: Germany | E4: DACH | F4: Independent Opticians | G4: Myopia Management | H4: 206834.21 | I4: 194026.17 | J4: 1477 | K4: 1403 | L4: 143273.53 | M4: 11826.68 | N4: 1429491.4 | O4: 11482 | P4: 12 | Q4: 19
A5: 44927 | B5: 2023 | C5: Jan | D5: Germany | E5: DACH | F5: Independent Opticians | G5: Occupational / Digital | H5: 389302.27 | I5: 374411.34 | J5: 3385 | K5: 3215 | L5: 243680.54 | M5: 12396.46 | N5: 2024932.3 | O5: 18828 | P5: 22 | Q5: 45
A6: 44927 | B6: 2023 | C6: Jan | D6: Germany | E6: DACH | F6: Optical Chains | G6: Single Vision | H6: 842749.23 | I6: 858430.26 | J6: 11705 | K6: 11888 | L6: 446222.12 | M6: 15404.16 | N6: 5105569.3 | O6: 79856 | P6: 35 | Q6: 141
A7: 44927 | B7: 2023 | C7: Jan | D7: Germany | E7: DACH | F7: Optical Chains | G7: Progressive | H7: 711249.36 | I7: 661325.09 | J7: 4064 | K7: 3837 | L7: 431749.41 | M7: 18263.76 | N7: 3824968.6 | O7: 22448 | P7: 29 | Q7: 48
A8: 44927 | B8: 2023 | C8: Jan | D8: Germany | E8: DACH | F8: Optical Chains | G8: Myopia Management | H8: 177838.36 | I8: 169497.6 | J8: 1270 | K8: 1228 | L8: 112728.87 | M8: 10229.33 | N8: 1198426.6 | O8: 9148 | P8: 10 | Q8: 22
A9: 44927 | B9: 2023 | C9: Jan | D9: Germany | E9: DACH | F9: Optical Chains | G9: Occupational / Digital | H9: 329922.34 | I9: 321334.44 | J9: 2869 | K9: 2832 | L9: 193604.68 | M9: 9361.31 | N9: 1802838.9 | O9: 16091 | P9: 14 | Q9: 31
A10: 44927 | B10: 2023 | C10: Jan | D10: Germany | E10: DACH | F10: E-commerce | G10: Single Vision | H10: 65234.13 | I10: 66011.69 | J10: 906 | K10: 910 | L10: 31143.81 | M10: 1149.7 | N10: 569362.07 | O10: 8447 | P10: 3 | Q10: 16
A11: 44927 | B11: 2023 | C11: Jan | D11: Germany | E11: DACH | F11: E-commerce | G11: Progressive | H11: 60515.71 | I11: 56283.8 | J11: 346 | K11: 325 | L11: 33950.32 | M11: 1482.45 | N11: 426037.07 | O11: 2752 | P11: 3 | Q11: 5
A12: 44927 | B12: 2023 | C12: Jan | D12: Germany | E12: DACH | F12: E-commerce | G12: Myopia Management | H12: 13651.02 | I12: 12677.51 | J12: 98 | K12: 90 | L12: 7997.98 | M12: 739.12 | N12: 127490.39 | O12: 932 | P12: 1 | Q12: 2
A13: 44927 | B13: 2023 | C13: Jan | D13: Germany | E13: DACH | F13: E-commerce | G13: Occupational / Digital | H13: 24196.11 | I13: 23567.12 | J13: 210 | K13: 206 | L13: 12860.14 | M13: 752.26 | N13: 203097.43 | O13: 1912 | P13: 1 | Q13: 3
... A3697: 46235 | B3697: 2026 | C3697: Aug | D3697: Austria | E3697: DACH | F3697: E-commerce | G3697: Occupational / Digital | H3697: 9531.43 | I3697: 9731.11 | J3697: 76 | K3697: 78 | L3697: 5092.84 | M3697: 299.15 | N3697: 83197.52 | O3697: 724 | P3697: 1 | Q3697: 2

Sheet Data_Dictionary
A1: Data Dictionary
A4: Column | B4: Type | C4: Definition | D4: Example | E4: Use in dashboard
A5: Month | B5: Date | C5: First day of the reporting month | D5: 44986 | E5: Time trends / monthly analysis
A6: Year | B6: Integer | C6: Calendar year | D6: 2025 | E6: Year filters / YoY analysis
A7: Month_Name | B7: Text | C7: Three-letter month label | D7: Mar | E7: Chart labels
A8: Country | B8: Text | C8: Sales market | D8: Germany | E8: Country slicer / ranking
A9: Region | B9: Text | C9: European region grouping | D9: DACH | E9: Regional comparison
A10: Channel | B10: Text | C10: Go-to-market channel | D10: Independent Opticians | E10: Channel mix
A11: Product_Category | B11: Text | C11: Lens category | D11: Progressive | E11: Product mix
A12: Revenue_EUR | B12: Currency | C12: Synthetic company revenue | D12: 1250000 | E12: Revenue KPI
A13: Revenue_Target_EUR | B13: Currency | C13: Synthetic revenue target | D13: 1300000 | E13: Target attainment
A14: Units_Sold | B14: Integer | C14: Synthetic unit sales | D14: 7200 | E14: Volume KPI
A15: Units_Target | B15: Integer | C15: Synthetic unit target | D15: 7000 | E15: Target attainment
A16: Gross_Profit_EUR | B16: Currency | C16: Revenue less synthetic cost of sales | D16: 780000 | E16: Gross margin %
A17: Marketing_Spend_EUR | B17: Currency | C17: Synthetic commercial / marketing spend | D17: 32000 | E17: Efficiency metric
A18: Market_Revenue_EUR | B18: Currency | C18: Synthetic total market revenue at same grain | D18: 8500000 | E18: Market share %
A19: Market_Units | B19: Integer | C19: Synthetic total market units at same grain | D19: 52000 | E19: Unit share / market context
A20: New_Accounts | B20: Integer | C20: Synthetic number of newly acquired B2B accounts | D20: 18 | E20: Commercial expansion
A21: Returns_Units | B21: Integer | C21: Synthetic returned units | D21: 96 | E21: Return rate / quality signal
A22: ASP_EUR | B22: Currency | C22: Revenue / Units Sold | D22: 71.96 | E22: Price / mix analysis
A23: Gross_Margin_% | B23: Percentage | C23: Gross Profit / Revenue | D23: 0.5584 | E23: Profitability
... A27: Revenue_per_Marketing_EUR | B27: Decimal | C27: Revenue / Marketing Spend | D27: 58.81 | E27: Commercial efficiency

Sheet Dashboard_Data
A1: Year | B1: 2026 | E1: Year | F1: 2026 | I1: Year | J1: 2026 | M1: Year | N1: 2026
E2: Month_Name | F2: (Mehrere Elemente) | I2: Month_Name | J2: (Mehrere Elemente) | M2: Month_Name | N2: (Mehrere Elemente)
A3: Month | B3: Revenue | C3: Target
A4: Jan | B4: 17610860 | C4: 17249020 | E4: Country | F4: Revenue | I4: Product Category | J4: Revenue | M4: Country | N4: Revenue | O4: Market Revenue | P4: Market Share | R4: Country | S4: Market Share | U4: Country | V4: Market Share
A5: Feb | B5: 17773721 | C5: 17482552 | E5: Germany | F5: 49037539 | I5: Progressive | J5: 53026068 | M5: Austria | N5: 9459112.8 | O5: 60062034 | P5: =N5/O5 -> 0.15748905 | R5: =M5 -> Austria | S5: =P5 -> 0.15748905 | U5: {=_xlfn.SORTBY(R5:S11,S5:S11, -1)} -> Germany | V5: 0.17688888
A6: Mrz | B6: 18620830 | C6: 18186599 | E6: France | F6: 28430416 | I6: Single Vision | J6: 50846543 | M6: France | N6: 28430416 | O6: 2.1594747e+08 | P6: =N6/O6 -> 0.13165432 | R6: =M6 -> France | S6: =P6 -> 0.13165432 | U6: Austria | V6: 0.15748905
A7: Apr | B7: 19064124 | C7: 18757741 | E7: Italy | F7: 18900032 | I7: Occupational / Digital | J7: 22730607 | M7: Germany | N7: 49037539 | O7: 2.7722228e+08 | P7: =N7/O7 -> 0.17688888 | R7: =M7 -> Germany | S7: =P7 -> 0.17688888 | U7: Netherlands | V7: 0.14747577
A8: Mai | B8: 18932319 | C8: 18481425 | E8: Spain | F8: 16538429 | I8: Myopia Management | J8: 17482671 | M8: Italy | N8: 18900032 | O8: 1.6530921e+08 | P8: =N8/O8 -> 0.11433139 | R8: =M8 -> Italy | S8: =P8 -> 0.11433139 | U8: France | V8: 0.13165432
A9: Jun | B9: 18299449 | C9: 17959018 | E9: Netherlands | F9: 11854286 | I9: Total | J9: 1.4408589e+08 | M9: Netherlands | N9: 11854286 | O9: 80381249 | P9: =N9/O9 -> 0.14747577 | R9: =M9 -> Netherlands | S9: =P9 -> 0.14747577 | U9: Italy | V9: 0.11433139
A10: Jul | B10: 17571556 | C10: 17255632 | E10: Poland | F10: 9866072.8 | M10: Poland | N10: 9866072.8 | O10: 1.0508259e+08 | P10: =N10/O10 -> 0.093888749 | R10: =M10 -> Poland | S10: =P10 -> 0.093888749 | U10: Spain | V10: 0.11360187
A11: Aug | B11: 16213029 | C11: 15854226 | E11: Austria | F11: 9459112.8 | M11: Spain | N11: 16538429 | O11: 1.4558237e+08 | P11: =N11/O11 -> 0.11360187 | R11: =M11 -> Spain | S11: =P11 -> 0.11360187 | U11: Poland | V11: 0.093888749
A12: Total | B12: 1.4408589e+08 | C12: 1.4122621e+08 | E12: Total | F12: 1.4408589e+08 | M12: Total | N12: 1.4408589e+08 | O12: 1.0495872e+09 | P12: =N12/O12 -> 0.13727863
